[2024-09-25 08:27:04,717] [autoreload.py:637] [autoreload:run_with_reloader] [INFO]- Watching for file changes with StatReloader
[2024-09-25 08:27:06,937] [basehttp.py:161] [basehttp:log_message] [INFO]- "GET / HTTP/1.1" 200 10330
[2024-09-25 08:27:07,089] [log.py:224] [log:log_response] [WARNING]- Not Found: /api/count
[2024-09-25 08:27:07,091] [basehttp.py:161] [basehttp:log_message] [WARNING]- "GET /api/count HTTP/1.1" 404 3142
[2024-09-25 08:27:16,165] [log.py:224] [log:log_response] [ERROR]- Internal Server Error: /userlogin/
Traceback (most recent call last):
  File "/usr/lib/python3.8/site-packages/urllib3/connection.py", line 169, in _new_conn
    conn = connection.create_connection(
  File "/usr/lib/python3.8/site-packages/urllib3/util/connection.py", line 96, in create_connection
    raise err
  File "/usr/lib/python3.8/site-packages/urllib3/util/connection.py", line 86, in create_connection
    sock.connect(sa)
ConnectionRefusedError: [Errno 111] Connection refused

During handling of the above exception, another exception occurred:

Traceback (most recent call last):
  File "/usr/lib/python3.8/site-packages/urllib3/connectionpool.py", line 699, in urlopen
    httplib_response = self._make_request(
  File "/usr/lib/python3.8/site-packages/urllib3/connectionpool.py", line 382, in _make_request
    self._validate_conn(conn)
  File "/usr/lib/python3.8/site-packages/urllib3/connectionpool.py", line 1010, in _validate_conn
    conn.connect()
  File "/usr/lib/python3.8/site-packages/urllib3/connection.py", line 353, in connect
    conn = self._new_conn()
  File "/usr/lib/python3.8/site-packages/urllib3/connection.py", line 181, in _new_conn
    raise NewConnectionError(
urllib3.exceptions.NewConnectionError: <urllib3.connection.HTTPSConnection object at 0xffff83fd4700>: Failed to establish a new connection: [Errno 111] Connection refused

During handling of the above exception, another exception occurred:

Traceback (most recent call last):
  File "/usr/lib/python3.8/site-packages/requests/adapters.py", line 439, in send
    resp = conn.urlopen(
  File "/usr/lib/python3.8/site-packages/urllib3/connectionpool.py", line 755, in urlopen
    retries = retries.increment(
  File "/usr/lib/python3.8/site-packages/urllib3/util/retry.py", line 573, in increment
    raise MaxRetryError(_pool, url, error or ResponseError(cause))
urllib3.exceptions.MaxRetryError: HTTPSConnectionPool(host='api.weixin.qq.com', port=443): Max retries exceeded with url: /sns/jscode2session?appid=wxa67ae78c4f1f6275&secret=7241b1950145a193f15b3584d50f3989&js_code=0b16T4Ga11PidI0LrzIa1og3SU06T4Gj&grant_type=authorization_code (Caused by NewConnectionError('<urllib3.connection.HTTPSConnection object at 0xffff83fd4700>: Failed to establish a new connection: [Errno 111] Connection refused'))

During handling of the above exception, another exception occurred:

Traceback (most recent call last):
  File "/root/.local/lib/python3.8/site-packages/django/core/handlers/exception.py", line 47, in inner
    response = get_response(request)
  File "/root/.local/lib/python3.8/site-packages/django/core/handlers/base.py", line 181, in _get_response
    response = wrapped_callback(request, *callback_args, **callback_kwargs)
  File "/root/.local/lib/python3.8/site-packages/django/views/decorators/csrf.py", line 54, in wrapped_view
    return view_func(*args, **kwargs)
  File "/root/.local/lib/python3.8/site-packages/django/views/generic/base.py", line 70, in view
    return self.dispatch(request, *args, **kwargs)
  File "/root/.local/lib/python3.8/site-packages/rest_framework/views.py", line 509, in dispatch
    response = self.handle_exception(exc)
  File "/root/.local/lib/python3.8/site-packages/rest_framework/views.py", line 469, in handle_exception
    self.raise_uncaught_exception(exc)
  File "/root/.local/lib/python3.8/site-packages/rest_framework/views.py", line 480, in raise_uncaught_exception
    raise exc
  File "/root/.local/lib/python3.8/site-packages/rest_framework/views.py", line 506, in dispatch
    response = handler(request, *args, **kwargs)
  File "/app/Professor_Student_Manage/views.py", line 114, in post
    res = requests.get(url, params=params)
  File "/usr/lib/python3.8/site-packages/requests/api.py", line 76, in get
    return request('get', url, params=params, **kwargs)
  File "/usr/lib/python3.8/site-packages/requests/api.py", line 61, in request
    return session.request(method=method, url=url, **kwargs)
  File "/usr/lib/python3.8/site-packages/requests/sessions.py", line 542, in request
    resp = self.send(prep, **send_kwargs)
  File "/usr/lib/python3.8/site-packages/requests/sessions.py", line 655, in send
    r = adapter.send(request, **kwargs)
  File "/usr/lib/python3.8/site-packages/requests/adapters.py", line 516, in send
    raise ConnectionError(e, request=request)
requests.exceptions.ConnectionError: HTTPSConnectionPool(host='api.weixin.qq.com', port=443): Max retries exceeded with url: /sns/jscode2session?appid=wxa67ae78c4f1f6275&secret=7241b1950145a193f15b3584d50f3989&js_code=0b16T4Ga11PidI0LrzIa1og3SU06T4Gj&grant_type=authorization_code (Caused by NewConnectionError('<urllib3.connection.HTTPSConnection object at 0xffff83fd4700>: Failed to establish a new connection: [Errno 111] Connection refused'))
[2024-09-25 08:27:16,168] [basehttp.py:161] [basehttp:log_message] [ERROR]- "POST /userlogin/ HTTP/1.1" 500 180960
[2024-09-25 08:27:50,736] [basehttp.py:161] [basehttp:log_message] [INFO]- "GET /admin/ HTTP/1.1" 200 11323
[2024-09-25 08:27:50,741] [basehttp.py:161] [basehttp:log_message] [INFO]- "GET /static/admin/img/icon-deletelink.svg HTTP/1.1" 200 392
[2024-09-25 08:27:50,742] [basehttp.py:161] [basehttp:log_message] [INFO]- "GET /static/admin/img/icon-changelink.svg HTTP/1.1" 200 380
[2024-09-25 08:27:50,742] [basehttp.py:161] [basehttp:log_message] [INFO]- "GET /static/admin/css/dashboard.css HTTP/1.1" 200 380
[2024-09-25 08:27:50,744] [basehttp.py:161] [basehttp:log_message] [INFO]- "GET /static/admin/css/responsive.css HTTP/1.1" 200 18545
[2024-09-25 08:27:50,745] [basehttp.py:161] [basehttp:log_message] [INFO]- "GET /static/admin/css/base.css HTTP/1.1" 200 19513
[2024-09-25 08:27:50,750] [basehttp.py:161] [basehttp:log_message] [INFO]- "GET /static/admin/css/nav_sidebar.css HTTP/1.1" 200 2271
[2024-09-25 08:27:50,752] [basehttp.py:161] [basehttp:log_message] [INFO]- "GET /static/admin/js/nav_sidebar.js HTTP/1.1" 200 1360
[2024-09-25 08:27:50,752] [basehttp.py:161] [basehttp:log_message] [INFO]- "GET /static/admin/css/fonts.css HTTP/1.1" 200 423
[2024-09-25 08:27:50,763] [basehttp.py:161] [basehttp:log_message] [INFO]- "GET /static/admin/fonts/Roboto-Regular-webfont.woff HTTP/1.1" 200 85876
[2024-09-25 08:27:50,765] [basehttp.py:161] [basehttp:log_message] [INFO]- "GET /static/admin/fonts/Roboto-Bold-webfont.woff HTTP/1.1" 200 86184
[2024-09-25 08:27:50,775] [basehttp.py:161] [basehttp:log_message] [INFO]- "GET /static/admin/img/icon-addlink.svg HTTP/1.1" 200 331
[2024-09-25 08:27:50,787] [basehttp.py:161] [basehttp:log_message] [INFO]- "GET /static/admin/fonts/Roboto-Light-webfont.woff HTTP/1.1" 200 85692
[2024-09-25 08:28:04,917] [log.py:224] [log:log_response] [ERROR]- Internal Server Error: /userlogin/
Traceback (most recent call last):
  File "/usr/lib/python3.8/site-packages/urllib3/connection.py", line 169, in _new_conn
    conn = connection.create_connection(
  File "/usr/lib/python3.8/site-packages/urllib3/util/connection.py", line 96, in create_connection
    raise err
  File "/usr/lib/python3.8/site-packages/urllib3/util/connection.py", line 86, in create_connection
    sock.connect(sa)
ConnectionRefusedError: [Errno 111] Connection refused

During handling of the above exception, another exception occurred:

Traceback (most recent call last):
  File "/usr/lib/python3.8/site-packages/urllib3/connectionpool.py", line 699, in urlopen
    httplib_response = self._make_request(
  File "/usr/lib/python3.8/site-packages/urllib3/connectionpool.py", line 382, in _make_request
    self._validate_conn(conn)
  File "/usr/lib/python3.8/site-packages/urllib3/connectionpool.py", line 1010, in _validate_conn
    conn.connect()
  File "/usr/lib/python3.8/site-packages/urllib3/connection.py", line 353, in connect
    conn = self._new_conn()
  File "/usr/lib/python3.8/site-packages/urllib3/connection.py", line 181, in _new_conn
    raise NewConnectionError(
urllib3.exceptions.NewConnectionError: <urllib3.connection.HTTPSConnection object at 0xffff83d81a90>: Failed to establish a new connection: [Errno 111] Connection refused

During handling of the above exception, another exception occurred:

Traceback (most recent call last):
  File "/usr/lib/python3.8/site-packages/requests/adapters.py", line 439, in send
    resp = conn.urlopen(
  File "/usr/lib/python3.8/site-packages/urllib3/connectionpool.py", line 755, in urlopen
    retries = retries.increment(
  File "/usr/lib/python3.8/site-packages/urllib3/util/retry.py", line 573, in increment
    raise MaxRetryError(_pool, url, error or ResponseError(cause))
urllib3.exceptions.MaxRetryError: HTTPSConnectionPool(host='api.weixin.qq.com', port=443): Max retries exceeded with url: /sns/jscode2session?appid=wxa67ae78c4f1f6275&secret=7241b1950145a193f15b3584d50f3989&js_code=0c1bW4Ga1ZJidI0atEGa1zwc9D1bW4GG&grant_type=authorization_code (Caused by NewConnectionError('<urllib3.connection.HTTPSConnection object at 0xffff83d81a90>: Failed to establish a new connection: [Errno 111] Connection refused'))

During handling of the above exception, another exception occurred:

Traceback (most recent call last):
  File "/root/.local/lib/python3.8/site-packages/django/core/handlers/exception.py", line 47, in inner
    response = get_response(request)
  File "/root/.local/lib/python3.8/site-packages/django/core/handlers/base.py", line 181, in _get_response
    response = wrapped_callback(request, *callback_args, **callback_kwargs)
  File "/root/.local/lib/python3.8/site-packages/django/views/decorators/csrf.py", line 54, in wrapped_view
    return view_func(*args, **kwargs)
  File "/root/.local/lib/python3.8/site-packages/django/views/generic/base.py", line 70, in view
    return self.dispatch(request, *args, **kwargs)
  File "/root/.local/lib/python3.8/site-packages/rest_framework/views.py", line 509, in dispatch
    response = self.handle_exception(exc)
  File "/root/.local/lib/python3.8/site-packages/rest_framework/views.py", line 469, in handle_exception
    self.raise_uncaught_exception(exc)
  File "/root/.local/lib/python3.8/site-packages/rest_framework/views.py", line 480, in raise_uncaught_exception
    raise exc
  File "/root/.local/lib/python3.8/site-packages/rest_framework/views.py", line 506, in dispatch
    response = handler(request, *args, **kwargs)
  File "/app/Professor_Student_Manage/views.py", line 114, in post
    res = requests.get(url, params=params)
  File "/usr/lib/python3.8/site-packages/requests/api.py", line 76, in get
    return request('get', url, params=params, **kwargs)
  File "/usr/lib/python3.8/site-packages/requests/api.py", line 61, in request
    return session.request(method=method, url=url, **kwargs)
  File "/usr/lib/python3.8/site-packages/requests/sessions.py", line 542, in request
    resp = self.send(prep, **send_kwargs)
  File "/usr/lib/python3.8/site-packages/requests/sessions.py", line 655, in send
    r = adapter.send(request, **kwargs)
  File "/usr/lib/python3.8/site-packages/requests/adapters.py", line 516, in send
    raise ConnectionError(e, request=request)
requests.exceptions.ConnectionError: HTTPSConnectionPool(host='api.weixin.qq.com', port=443): Max retries exceeded with url: /sns/jscode2session?appid=wxa67ae78c4f1f6275&secret=7241b1950145a193f15b3584d50f3989&js_code=0c1bW4Ga1ZJidI0atEGa1zwc9D1bW4GG&grant_type=authorization_code (Caused by NewConnectionError('<urllib3.connection.HTTPSConnection object at 0xffff83d81a90>: Failed to establish a new connection: [Errno 111] Connection refused'))
[2024-09-25 08:28:04,920] [basehttp.py:161] [basehttp:log_message] [ERROR]- "POST /userlogin/ HTTP/1.1" 500 180961
[2024-09-25 08:30:53,400] [log.py:224] [log:log_response] [ERROR]- Internal Server Error: /userlogin/
Traceback (most recent call last):
  File "/usr/lib/python3.8/site-packages/urllib3/connection.py", line 169, in _new_conn
    conn = connection.create_connection(
  File "/usr/lib/python3.8/site-packages/urllib3/util/connection.py", line 96, in create_connection
    raise err
  File "/usr/lib/python3.8/site-packages/urllib3/util/connection.py", line 86, in create_connection
    sock.connect(sa)
ConnectionRefusedError: [Errno 111] Connection refused

During handling of the above exception, another exception occurred:

Traceback (most recent call last):
  File "/usr/lib/python3.8/site-packages/urllib3/connectionpool.py", line 699, in urlopen
    httplib_response = self._make_request(
  File "/usr/lib/python3.8/site-packages/urllib3/connectionpool.py", line 382, in _make_request
    self._validate_conn(conn)
  File "/usr/lib/python3.8/site-packages/urllib3/connectionpool.py", line 1010, in _validate_conn
    conn.connect()
  File "/usr/lib/python3.8/site-packages/urllib3/connection.py", line 353, in connect
    conn = self._new_conn()
  File "/usr/lib/python3.8/site-packages/urllib3/connection.py", line 181, in _new_conn
    raise NewConnectionError(
urllib3.exceptions.NewConnectionError: <urllib3.connection.HTTPSConnection object at 0xffff83d99280>: Failed to establish a new connection: [Errno 111] Connection refused

During handling of the above exception, another exception occurred:

Traceback (most recent call last):
  File "/usr/lib/python3.8/site-packages/requests/adapters.py", line 439, in send
    resp = conn.urlopen(
  File "/usr/lib/python3.8/site-packages/urllib3/connectionpool.py", line 755, in urlopen
    retries = retries.increment(
  File "/usr/lib/python3.8/site-packages/urllib3/util/retry.py", line 573, in increment
    raise MaxRetryError(_pool, url, error or ResponseError(cause))
urllib3.exceptions.MaxRetryError: HTTPSConnectionPool(host='api.weixin.qq.com', port=443): Max retries exceeded with url: /sns/jscode2session?appid=wxa67ae78c4f1f6275&secret=7241b1950145a193f15b3584d50f3989&js_code=0c1J0xFa1ZaRdI06BlJa1jNvhY0J0xFP&grant_type=authorization_code (Caused by NewConnectionError('<urllib3.connection.HTTPSConnection object at 0xffff83d99280>: Failed to establish a new connection: [Errno 111] Connection refused'))

During handling of the above exception, another exception occurred:

Traceback (most recent call last):
  File "/root/.local/lib/python3.8/site-packages/django/core/handlers/exception.py", line 47, in inner
    response = get_response(request)
  File "/root/.local/lib/python3.8/site-packages/django/core/handlers/base.py", line 181, in _get_response
    response = wrapped_callback(request, *callback_args, **callback_kwargs)
  File "/root/.local/lib/python3.8/site-packages/django/views/decorators/csrf.py", line 54, in wrapped_view
    return view_func(*args, **kwargs)
  File "/root/.local/lib/python3.8/site-packages/django/views/generic/base.py", line 70, in view
    return self.dispatch(request, *args, **kwargs)
  File "/root/.local/lib/python3.8/site-packages/rest_framework/views.py", line 509, in dispatch
    response = self.handle_exception(exc)
  File "/root/.local/lib/python3.8/site-packages/rest_framework/views.py", line 469, in handle_exception
    self.raise_uncaught_exception(exc)
  File "/root/.local/lib/python3.8/site-packages/rest_framework/views.py", line 480, in raise_uncaught_exception
    raise exc
  File "/root/.local/lib/python3.8/site-packages/rest_framework/views.py", line 506, in dispatch
    response = handler(request, *args, **kwargs)
  File "/app/Professor_Student_Manage/views.py", line 114, in post
    res = requests.get(url, params=params)
  File "/usr/lib/python3.8/site-packages/requests/api.py", line 76, in get
    return request('get', url, params=params, **kwargs)
  File "/usr/lib/python3.8/site-packages/requests/api.py", line 61, in request
    return session.request(method=method, url=url, **kwargs)
  File "/usr/lib/python3.8/site-packages/requests/sessions.py", line 542, in request
    resp = self.send(prep, **send_kwargs)
  File "/usr/lib/python3.8/site-packages/requests/sessions.py", line 655, in send
    r = adapter.send(request, **kwargs)
  File "/usr/lib/python3.8/site-packages/requests/adapters.py", line 516, in send
    raise ConnectionError(e, request=request)
requests.exceptions.ConnectionError: HTTPSConnectionPool(host='api.weixin.qq.com', port=443): Max retries exceeded with url: /sns/jscode2session?appid=wxa67ae78c4f1f6275&secret=7241b1950145a193f15b3584d50f3989&js_code=0c1J0xFa1ZaRdI06BlJa1jNvhY0J0xFP&grant_type=authorization_code (Caused by NewConnectionError('<urllib3.connection.HTTPSConnection object at 0xffff83d99280>: Failed to establish a new connection: [Errno 111] Connection refused'))
[2024-09-25 08:30:53,403] [basehttp.py:161] [basehttp:log_message] [ERROR]- "POST /userlogin/ HTTP/1.1" 500 180961
[2024-09-25 08:31:05,844] [log.py:224] [log:log_response] [ERROR]- Internal Server Error: /userlogin/
Traceback (most recent call last):
  File "/usr/lib/python3.8/site-packages/urllib3/connection.py", line 169, in _new_conn
    conn = connection.create_connection(
  File "/usr/lib/python3.8/site-packages/urllib3/util/connection.py", line 96, in create_connection
    raise err
  File "/usr/lib/python3.8/site-packages/urllib3/util/connection.py", line 86, in create_connection
    sock.connect(sa)
ConnectionRefusedError: [Errno 111] Connection refused

During handling of the above exception, another exception occurred:

Traceback (most recent call last):
  File "/usr/lib/python3.8/site-packages/urllib3/connectionpool.py", line 699, in urlopen
    httplib_response = self._make_request(
  File "/usr/lib/python3.8/site-packages/urllib3/connectionpool.py", line 382, in _make_request
    self._validate_conn(conn)
  File "/usr/lib/python3.8/site-packages/urllib3/connectionpool.py", line 1010, in _validate_conn
    conn.connect()
  File "/usr/lib/python3.8/site-packages/urllib3/connection.py", line 353, in connect
    conn = self._new_conn()
  File "/usr/lib/python3.8/site-packages/urllib3/connection.py", line 181, in _new_conn
    raise NewConnectionError(
urllib3.exceptions.NewConnectionError: <urllib3.connection.HTTPSConnection object at 0xffff83d86520>: Failed to establish a new connection: [Errno 111] Connection refused

During handling of the above exception, another exception occurred:

Traceback (most recent call last):
  File "/usr/lib/python3.8/site-packages/requests/adapters.py", line 439, in send
    resp = conn.urlopen(
  File "/usr/lib/python3.8/site-packages/urllib3/connectionpool.py", line 755, in urlopen
    retries = retries.increment(
  File "/usr/lib/python3.8/site-packages/urllib3/util/retry.py", line 573, in increment
    raise MaxRetryError(_pool, url, error or ResponseError(cause))
urllib3.exceptions.MaxRetryError: HTTPSConnectionPool(host='api.weixin.qq.com', port=443): Max retries exceeded with url: /sns/jscode2session?appid=wxa67ae78c4f1f6275&secret=7241b1950145a193f15b3584d50f3989&js_code=0b14PL000X8CSS1SFj100au2mr04PL0y&grant_type=authorization_code (Caused by NewConnectionError('<urllib3.connection.HTTPSConnection object at 0xffff83d86520>: Failed to establish a new connection: [Errno 111] Connection refused'))

During handling of the above exception, another exception occurred:

Traceback (most recent call last):
  File "/root/.local/lib/python3.8/site-packages/django/core/handlers/exception.py", line 47, in inner
    response = get_response(request)
  File "/root/.local/lib/python3.8/site-packages/django/core/handlers/base.py", line 181, in _get_response
    response = wrapped_callback(request, *callback_args, **callback_kwargs)
  File "/root/.local/lib/python3.8/site-packages/django/views/decorators/csrf.py", line 54, in wrapped_view
    return view_func(*args, **kwargs)
  File "/root/.local/lib/python3.8/site-packages/django/views/generic/base.py", line 70, in view
    return self.dispatch(request, *args, **kwargs)
  File "/root/.local/lib/python3.8/site-packages/rest_framework/views.py", line 509, in dispatch
    response = self.handle_exception(exc)
  File "/root/.local/lib/python3.8/site-packages/rest_framework/views.py", line 469, in handle_exception
    self.raise_uncaught_exception(exc)
  File "/root/.local/lib/python3.8/site-packages/rest_framework/views.py", line 480, in raise_uncaught_exception
    raise exc
  File "/root/.local/lib/python3.8/site-packages/rest_framework/views.py", line 506, in dispatch
    response = handler(request, *args, **kwargs)
  File "/app/Professor_Student_Manage/views.py", line 114, in post
    res = requests.get(url, params=params)
  File "/usr/lib/python3.8/site-packages/requests/api.py", line 76, in get
    return request('get', url, params=params, **kwargs)
  File "/usr/lib/python3.8/site-packages/requests/api.py", line 61, in request
    return session.request(method=method, url=url, **kwargs)
  File "/usr/lib/python3.8/site-packages/requests/sessions.py", line 542, in request
    resp = self.send(prep, **send_kwargs)
  File "/usr/lib/python3.8/site-packages/requests/sessions.py", line 655, in send
    r = adapter.send(request, **kwargs)
  File "/usr/lib/python3.8/site-packages/requests/adapters.py", line 516, in send
    raise ConnectionError(e, request=request)
requests.exceptions.ConnectionError: HTTPSConnectionPool(host='api.weixin.qq.com', port=443): Max retries exceeded with url: /sns/jscode2session?appid=wxa67ae78c4f1f6275&secret=7241b1950145a193f15b3584d50f3989&js_code=0b14PL000X8CSS1SFj100au2mr04PL0y&grant_type=authorization_code (Caused by NewConnectionError('<urllib3.connection.HTTPSConnection object at 0xffff83d86520>: Failed to establish a new connection: [Errno 111] Connection refused'))
[2024-09-25 08:31:05,845] [basehttp.py:161] [basehttp:log_message] [ERROR]- "POST /userlogin/ HTTP/1.1" 500 180961
[2024-09-25 08:31:18,912] [basehttp.py:161] [basehttp:log_message] [INFO]- "GET /admin/ HTTP/1.1" 200 11323
[2024-09-25 08:31:18,921] [basehttp.py:161] [basehttp:log_message] [INFO]- "GET /static/admin/css/dashboard.css HTTP/1.1" 304 0
[2024-09-25 08:31:18,927] [basehttp.py:161] [basehttp:log_message] [INFO]- "GET /static/admin/css/responsive.css HTTP/1.1" 304 0
[2024-09-25 08:31:18,928] [basehttp.py:161] [basehttp:log_message] [INFO]- "GET /static/admin/css/nav_sidebar.css HTTP/1.1" 304 0
[2024-09-25 08:31:18,929] [basehttp.py:161] [basehttp:log_message] [INFO]- "GET /static/admin/css/base.css HTTP/1.1" 304 0
[2024-09-25 08:31:18,929] [basehttp.py:161] [basehttp:log_message] [INFO]- "GET /static/admin/js/nav_sidebar.js HTTP/1.1" 304 0
[2024-09-25 08:31:18,933] [basehttp.py:161] [basehttp:log_message] [INFO]- "GET /static/admin/css/fonts.css HTTP/1.1" 304 0
[2024-09-25 08:31:18,939] [basehttp.py:161] [basehttp:log_message] [INFO]- "GET /static/admin/fonts/Roboto-Regular-webfont.woff HTTP/1.1" 304 0
[2024-09-25 08:31:18,942] [basehttp.py:161] [basehttp:log_message] [INFO]- "GET /static/admin/img/icon-addlink.svg HTTP/1.1" 304 0
[2024-09-25 08:31:18,943] [basehttp.py:161] [basehttp:log_message] [INFO]- "GET /static/admin/fonts/Roboto-Bold-webfont.woff HTTP/1.1" 304 0
[2024-09-25 08:31:18,943] [basehttp.py:161] [basehttp:log_message] [INFO]- "GET /static/admin/img/icon-changelink.svg HTTP/1.1" 304 0
[2024-09-25 08:31:18,944] [basehttp.py:161] [basehttp:log_message] [INFO]- "GET /static/admin/fonts/Roboto-Light-webfont.woff HTTP/1.1" 304 0
[2024-09-25 08:31:18,945] [basehttp.py:161] [basehttp:log_message] [INFO]- "GET /static/admin/img/icon-deletelink.svg HTTP/1.1" 304 0
[2024-09-25 08:31:21,358] [basehttp.py:161] [basehttp:log_message] [INFO]- "GET /admin/Select_Information/studentprofessorchoice/ HTTP/1.1" 200 66138
[2024-09-25 08:31:21,387] [basehttp.py:161] [basehttp:log_message] [INFO]- "GET /static/admin/js/jquery.init.js HTTP/1.1" 200 347
[2024-09-25 08:31:21,387] [basehttp.py:161] [basehttp:log_message] [INFO]- "GET /static/admin/css/changelists.css HTTP/1.1" 200 6874
[2024-09-25 08:31:21,388] [basehttp.py:161] [basehttp:log_message] [INFO]- "GET /static/admin/js/actions.js HTTP/1.1" 200 7867
[2024-09-25 08:31:21,394] [basehttp.py:161] [basehttp:log_message] [INFO]- "GET /static/admin/js/prepopulate.js HTTP/1.1" 200 1531
[2024-09-25 08:31:21,395] [basehttp.py:161] [basehttp:log_message] [INFO]- "GET /static/admin/js/core.js HTTP/1.1" 200 5698
[2024-09-25 08:31:21,395] [basehttp.py:161] [basehttp:log_message] [INFO]- "GET /static/admin/js/admin/RelatedObjectLookups.js HTTP/1.1" 200 5984
[2024-09-25 08:31:21,397] [basehttp.py:161] [basehttp:log_message] [INFO]- "GET /static/admin/js/urlify.js HTTP/1.1" 200 7902
[2024-09-25 08:31:21,399] [basehttp.py:161] [basehttp:log_message] [INFO]- "GET /static/admin/img/search.svg HTTP/1.1" 200 458
[2024-09-25 08:31:21,401] [basehttp.py:161] [basehttp:log_message] [INFO]- "GET /static/admin/img/icon-no.svg HTTP/1.1" 200 560
[2024-09-25 08:31:21,404] [basehttp.py:161] [basehttp:log_message] [INFO]- "GET /static/admin/img/icon-yes.svg HTTP/1.1" 200 436
[2024-09-25 08:31:21,406] [basehttp.py:161] [basehttp:log_message] [INFO]- "GET /static/admin/js/vendor/xregexp/xregexp.js HTTP/1.1" 200 232381
[2024-09-25 08:31:21,407] [basehttp.py:161] [basehttp:log_message] [INFO]- "GET /static/admin/js/vendor/jquery/jquery.js HTTP/1.1" 200 287630
[2024-09-25 08:31:21,683] [basehttp.py:161] [basehttp:log_message] [INFO]- "GET /admin/jsi18n/ HTTP/1.1" 200 8398
[2024-09-25 08:31:21,724] [basehttp.py:161] [basehttp:log_message] [INFO]- "GET /static/admin/img/tooltag-add.svg HTTP/1.1" 200 331
[2024-09-25 08:31:28,279] [basehttp.py:161] [basehttp:log_message] [INFO]- "GET /admin/Professor_Student_Manage/student/ HTTP/1.1" 200 69951
[2024-09-25 08:31:28,614] [basehttp.py:161] [basehttp:log_message] [INFO]- "GET /admin/jsi18n/ HTTP/1.1" 200 8398
[2024-09-25 08:31:56,381] [log.py:224] [log:log_response] [ERROR]- Internal Server Error: /userlogin/
Traceback (most recent call last):
  File "/usr/lib/python3.8/site-packages/urllib3/connection.py", line 169, in _new_conn
    conn = connection.create_connection(
  File "/usr/lib/python3.8/site-packages/urllib3/util/connection.py", line 96, in create_connection
    raise err
  File "/usr/lib/python3.8/site-packages/urllib3/util/connection.py", line 86, in create_connection
    sock.connect(sa)
ConnectionRefusedError: [Errno 111] Connection refused

During handling of the above exception, another exception occurred:

Traceback (most recent call last):
  File "/usr/lib/python3.8/site-packages/urllib3/connectionpool.py", line 699, in urlopen
    httplib_response = self._make_request(
  File "/usr/lib/python3.8/site-packages/urllib3/connectionpool.py", line 382, in _make_request
    self._validate_conn(conn)
  File "/usr/lib/python3.8/site-packages/urllib3/connectionpool.py", line 1010, in _validate_conn
    conn.connect()
  File "/usr/lib/python3.8/site-packages/urllib3/connection.py", line 353, in connect
    conn = self._new_conn()
  File "/usr/lib/python3.8/site-packages/urllib3/connection.py", line 181, in _new_conn
    raise NewConnectionError(
urllib3.exceptions.NewConnectionError: <urllib3.connection.HTTPSConnection object at 0xffff8416e6d0>: Failed to establish a new connection: [Errno 111] Connection refused

During handling of the above exception, another exception occurred:

Traceback (most recent call last):
  File "/usr/lib/python3.8/site-packages/requests/adapters.py", line 439, in send
    resp = conn.urlopen(
  File "/usr/lib/python3.8/site-packages/urllib3/connectionpool.py", line 755, in urlopen
    retries = retries.increment(
  File "/usr/lib/python3.8/site-packages/urllib3/util/retry.py", line 573, in increment
    raise MaxRetryError(_pool, url, error or ResponseError(cause))
urllib3.exceptions.MaxRetryError: HTTPSConnectionPool(host='api.weixin.qq.com', port=443): Max retries exceeded with url: /sns/jscode2session?appid=wxa67ae78c4f1f6275&secret=7241b1950145a193f15b3584d50f3989&js_code=0d1NLH0w3MsVx33M4f4w3vIzMw2NLH0c&grant_type=authorization_code (Caused by NewConnectionError('<urllib3.connection.HTTPSConnection object at 0xffff8416e6d0>: Failed to establish a new connection: [Errno 111] Connection refused'))

During handling of the above exception, another exception occurred:

Traceback (most recent call last):
  File "/root/.local/lib/python3.8/site-packages/django/core/handlers/exception.py", line 47, in inner
    response = get_response(request)
  File "/root/.local/lib/python3.8/site-packages/django/core/handlers/base.py", line 181, in _get_response
    response = wrapped_callback(request, *callback_args, **callback_kwargs)
  File "/root/.local/lib/python3.8/site-packages/django/views/decorators/csrf.py", line 54, in wrapped_view
    return view_func(*args, **kwargs)
  File "/root/.local/lib/python3.8/site-packages/django/views/generic/base.py", line 70, in view
    return self.dispatch(request, *args, **kwargs)
  File "/root/.local/lib/python3.8/site-packages/rest_framework/views.py", line 509, in dispatch
    response = self.handle_exception(exc)
  File "/root/.local/lib/python3.8/site-packages/rest_framework/views.py", line 469, in handle_exception
    self.raise_uncaught_exception(exc)
  File "/root/.local/lib/python3.8/site-packages/rest_framework/views.py", line 480, in raise_uncaught_exception
    raise exc
  File "/root/.local/lib/python3.8/site-packages/rest_framework/views.py", line 506, in dispatch
    response = handler(request, *args, **kwargs)
  File "/app/Professor_Student_Manage/views.py", line 114, in post
    res = requests.get(url, params=params)
  File "/usr/lib/python3.8/site-packages/requests/api.py", line 76, in get
    return request('get', url, params=params, **kwargs)
  File "/usr/lib/python3.8/site-packages/requests/api.py", line 61, in request
    return session.request(method=method, url=url, **kwargs)
  File "/usr/lib/python3.8/site-packages/requests/sessions.py", line 542, in request
    resp = self.send(prep, **send_kwargs)
  File "/usr/lib/python3.8/site-packages/requests/sessions.py", line 655, in send
    r = adapter.send(request, **kwargs)
  File "/usr/lib/python3.8/site-packages/requests/adapters.py", line 516, in send
    raise ConnectionError(e, request=request)
requests.exceptions.ConnectionError: HTTPSConnectionPool(host='api.weixin.qq.com', port=443): Max retries exceeded with url: /sns/jscode2session?appid=wxa67ae78c4f1f6275&secret=7241b1950145a193f15b3584d50f3989&js_code=0d1NLH0w3MsVx33M4f4w3vIzMw2NLH0c&grant_type=authorization_code (Caused by NewConnectionError('<urllib3.connection.HTTPSConnection object at 0xffff8416e6d0>: Failed to establish a new connection: [Errno 111] Connection refused'))
[2024-09-25 08:31:56,383] [basehttp.py:161] [basehttp:log_message] [ERROR]- "POST /userlogin/ HTTP/1.1" 500 180961
[2024-09-25 08:32:54,815] [basehttp.py:161] [basehttp:log_message] [INFO]- "GET / HTTP/1.1" 200 10330
[2024-09-25 08:32:59,681] [basehttp.py:161] [basehttp:log_message] [INFO]- "GET /admin HTTP/1.1" 301 0
[2024-09-25 08:32:59,704] [basehttp.py:161] [basehttp:log_message] [INFO]- "GET /admin/ HTTP/1.1" 302 0
[2024-09-25 08:32:59,731] [basehttp.py:161] [basehttp:log_message] [INFO]- "GET /admin/login/?next=/admin/ HTTP/1.1" 200 2216
[2024-09-25 08:32:59,746] [basehttp.py:161] [basehttp:log_message] [INFO]- "GET /static/admin/css/nav_sidebar.css HTTP/1.1" 200 2271
[2024-09-25 08:32:59,746] [basehttp.py:161] [basehttp:log_message] [INFO]- "GET /static/admin/css/login.css HTTP/1.1" 200 939
[2024-09-25 08:32:59,746] [basehttp.py:161] [basehttp:log_message] [INFO]- "GET /static/admin/css/base.css HTTP/1.1" 200 19513
[2024-09-25 08:32:59,746] [basehttp.py:161] [basehttp:log_message] [INFO]- "GET /static/admin/js/nav_sidebar.js HTTP/1.1" 200 1360
[2024-09-25 08:32:59,747] [basehttp.py:161] [basehttp:log_message] [INFO]- "GET /static/admin/css/responsive.css HTTP/1.1" 200 18545
[2024-09-25 08:32:59,751] [basehttp.py:161] [basehttp:log_message] [INFO]- "GET /static/admin/css/fonts.css HTTP/1.1" 200 423
[2024-09-25 08:32:59,760] [basehttp.py:161] [basehttp:log_message] [INFO]- "GET /static/admin/fonts/Roboto-Regular-webfont.woff HTTP/1.1" 200 85876
[2024-09-25 08:32:59,770] [basehttp.py:161] [basehttp:log_message] [INFO]- "GET /static/admin/fonts/Roboto-Light-webfont.woff HTTP/1.1" 200 85692
[2024-09-25 08:32:59,812] [log.py:224] [log:log_response] [WARNING]- Not Found: /favicon.ico
[2024-09-25 08:32:59,813] [basehttp.py:161] [basehttp:log_message] [INFO]- "GET /static/admin/fonts/Roboto-Bold-webfont.woff HTTP/1.1" 200 86184
[2024-09-25 08:32:59,814] [basehttp.py:161] [basehttp:log_message] [WARNING]- "GET /favicon.ico HTTP/1.1" 404 3148
[2024-09-25 08:33:06,821] [basehttp.py:161] [basehttp:log_message] [INFO]- "POST /admin/login/?next=/admin/ HTTP/1.1" 302 0
[2024-09-25 08:33:07,244] [basehttp.py:161] [basehttp:log_message] [INFO]- "GET /admin/ HTTP/1.1" 200 11323
[2024-09-25 08:33:07,258] [basehttp.py:161] [basehttp:log_message] [INFO]- "GET /static/admin/css/dashboard.css HTTP/1.1" 200 380
[2024-09-25 08:33:07,275] [basehttp.py:161] [basehttp:log_message] [INFO]- "GET /static/admin/img/icon-deletelink.svg HTTP/1.1" 200 392
[2024-09-25 08:33:07,275] [basehttp.py:161] [basehttp:log_message] [INFO]- "GET /static/admin/img/icon-addlink.svg HTTP/1.1" 200 331
[2024-09-25 08:33:07,275] [basehttp.py:161] [basehttp:log_message] [INFO]- "GET /static/admin/img/icon-changelink.svg HTTP/1.1" 200 380
[2024-09-25 08:33:28,580] [log.py:224] [log:log_response] [ERROR]- Internal Server Error: /userlogin/
Traceback (most recent call last):
  File "/usr/lib/python3.8/site-packages/urllib3/connection.py", line 169, in _new_conn
    conn = connection.create_connection(
  File "/usr/lib/python3.8/site-packages/urllib3/util/connection.py", line 96, in create_connection
    raise err
  File "/usr/lib/python3.8/site-packages/urllib3/util/connection.py", line 86, in create_connection
    sock.connect(sa)
ConnectionRefusedError: [Errno 111] Connection refused

During handling of the above exception, another exception occurred:

Traceback (most recent call last):
  File "/usr/lib/python3.8/site-packages/urllib3/connectionpool.py", line 699, in urlopen
    httplib_response = self._make_request(
  File "/usr/lib/python3.8/site-packages/urllib3/connectionpool.py", line 382, in _make_request
    self._validate_conn(conn)
  File "/usr/lib/python3.8/site-packages/urllib3/connectionpool.py", line 1010, in _validate_conn
    conn.connect()
  File "/usr/lib/python3.8/site-packages/urllib3/connection.py", line 353, in connect
    conn = self._new_conn()
  File "/usr/lib/python3.8/site-packages/urllib3/connection.py", line 181, in _new_conn
    raise NewConnectionError(
urllib3.exceptions.NewConnectionError: <urllib3.connection.HTTPSConnection object at 0xffff83d2ce80>: Failed to establish a new connection: [Errno 111] Connection refused

During handling of the above exception, another exception occurred:

Traceback (most recent call last):
  File "/usr/lib/python3.8/site-packages/requests/adapters.py", line 439, in send
    resp = conn.urlopen(
  File "/usr/lib/python3.8/site-packages/urllib3/connectionpool.py", line 755, in urlopen
    retries = retries.increment(
  File "/usr/lib/python3.8/site-packages/urllib3/util/retry.py", line 573, in increment
    raise MaxRetryError(_pool, url, error or ResponseError(cause))
urllib3.exceptions.MaxRetryError: HTTPSConnectionPool(host='api.weixin.qq.com', port=443): Max retries exceeded with url: /sns/jscode2session?appid=wxa67ae78c4f1f6275&secret=7241b1950145a193f15b3584d50f3989&js_code=0b1ZRd0005JbTS1niG000pzeWT3ZRd0V&grant_type=authorization_code (Caused by NewConnectionError('<urllib3.connection.HTTPSConnection object at 0xffff83d2ce80>: Failed to establish a new connection: [Errno 111] Connection refused'))

During handling of the above exception, another exception occurred:

Traceback (most recent call last):
  File "/root/.local/lib/python3.8/site-packages/django/core/handlers/exception.py", line 47, in inner
    response = get_response(request)
  File "/root/.local/lib/python3.8/site-packages/django/core/handlers/base.py", line 181, in _get_response
    response = wrapped_callback(request, *callback_args, **callback_kwargs)
  File "/root/.local/lib/python3.8/site-packages/django/views/decorators/csrf.py", line 54, in wrapped_view
    return view_func(*args, **kwargs)
  File "/root/.local/lib/python3.8/site-packages/django/views/generic/base.py", line 70, in view
    return self.dispatch(request, *args, **kwargs)
  File "/root/.local/lib/python3.8/site-packages/rest_framework/views.py", line 509, in dispatch
    response = self.handle_exception(exc)
  File "/root/.local/lib/python3.8/site-packages/rest_framework/views.py", line 469, in handle_exception
    self.raise_uncaught_exception(exc)
  File "/root/.local/lib/python3.8/site-packages/rest_framework/views.py", line 480, in raise_uncaught_exception
    raise exc
  File "/root/.local/lib/python3.8/site-packages/rest_framework/views.py", line 506, in dispatch
    response = handler(request, *args, **kwargs)
  File "/app/Professor_Student_Manage/views.py", line 114, in post
    res = requests.get(url, params=params)
  File "/usr/lib/python3.8/site-packages/requests/api.py", line 76, in get
    return request('get', url, params=params, **kwargs)
  File "/usr/lib/python3.8/site-packages/requests/api.py", line 61, in request
    return session.request(method=method, url=url, **kwargs)
  File "/usr/lib/python3.8/site-packages/requests/sessions.py", line 542, in request
    resp = self.send(prep, **send_kwargs)
  File "/usr/lib/python3.8/site-packages/requests/sessions.py", line 655, in send
    r = adapter.send(request, **kwargs)
  File "/usr/lib/python3.8/site-packages/requests/adapters.py", line 516, in send
    raise ConnectionError(e, request=request)
requests.exceptions.ConnectionError: HTTPSConnectionPool(host='api.weixin.qq.com', port=443): Max retries exceeded with url: /sns/jscode2session?appid=wxa67ae78c4f1f6275&secret=7241b1950145a193f15b3584d50f3989&js_code=0b1ZRd0005JbTS1niG000pzeWT3ZRd0V&grant_type=authorization_code (Caused by NewConnectionError('<urllib3.connection.HTTPSConnection object at 0xffff83d2ce80>: Failed to establish a new connection: [Errno 111] Connection refused'))
[2024-09-25 08:33:28,583] [basehttp.py:161] [basehttp:log_message] [ERROR]- "POST /userlogin/ HTTP/1.1" 500 180961
[2024-09-25 08:33:49,162] [log.py:224] [log:log_response] [ERROR]- Internal Server Error: /userlogin/
Traceback (most recent call last):
  File "/usr/lib/python3.8/site-packages/urllib3/connection.py", line 169, in _new_conn
    conn = connection.create_connection(
  File "/usr/lib/python3.8/site-packages/urllib3/util/connection.py", line 96, in create_connection
    raise err
  File "/usr/lib/python3.8/site-packages/urllib3/util/connection.py", line 86, in create_connection
    sock.connect(sa)
ConnectionRefusedError: [Errno 111] Connection refused

During handling of the above exception, another exception occurred:

Traceback (most recent call last):
  File "/usr/lib/python3.8/site-packages/urllib3/connectionpool.py", line 699, in urlopen
    httplib_response = self._make_request(
  File "/usr/lib/python3.8/site-packages/urllib3/connectionpool.py", line 382, in _make_request
    self._validate_conn(conn)
  File "/usr/lib/python3.8/site-packages/urllib3/connectionpool.py", line 1010, in _validate_conn
    conn.connect()
  File "/usr/lib/python3.8/site-packages/urllib3/connection.py", line 353, in connect
    conn = self._new_conn()
  File "/usr/lib/python3.8/site-packages/urllib3/connection.py", line 181, in _new_conn
    raise NewConnectionError(
urllib3.exceptions.NewConnectionError: <urllib3.connection.HTTPSConnection object at 0xffff83bdabb0>: Failed to establish a new connection: [Errno 111] Connection refused

During handling of the above exception, another exception occurred:

Traceback (most recent call last):
  File "/usr/lib/python3.8/site-packages/requests/adapters.py", line 439, in send
    resp = conn.urlopen(
  File "/usr/lib/python3.8/site-packages/urllib3/connectionpool.py", line 755, in urlopen
    retries = retries.increment(
  File "/usr/lib/python3.8/site-packages/urllib3/util/retry.py", line 573, in increment
    raise MaxRetryError(_pool, url, error or ResponseError(cause))
urllib3.exceptions.MaxRetryError: HTTPSConnectionPool(host='api.weixin.qq.com', port=443): Max retries exceeded with url: /sns/jscode2session?appid=wxa67ae78c4f1f6275&secret=7241b1950145a193f15b3584d50f3989&js_code=0d1p5k100DUhUS1E9M3005bvUd3p5k1r&grant_type=authorization_code (Caused by NewConnectionError('<urllib3.connection.HTTPSConnection object at 0xffff83bdabb0>: Failed to establish a new connection: [Errno 111] Connection refused'))

During handling of the above exception, another exception occurred:

Traceback (most recent call last):
  File "/root/.local/lib/python3.8/site-packages/django/core/handlers/exception.py", line 47, in inner
    response = get_response(request)
  File "/root/.local/lib/python3.8/site-packages/django/core/handlers/base.py", line 181, in _get_response
    response = wrapped_callback(request, *callback_args, **callback_kwargs)
  File "/root/.local/lib/python3.8/site-packages/django/views/decorators/csrf.py", line 54, in wrapped_view
    return view_func(*args, **kwargs)
  File "/root/.local/lib/python3.8/site-packages/django/views/generic/base.py", line 70, in view
    return self.dispatch(request, *args, **kwargs)
  File "/root/.local/lib/python3.8/site-packages/rest_framework/views.py", line 509, in dispatch
    response = self.handle_exception(exc)
  File "/root/.local/lib/python3.8/site-packages/rest_framework/views.py", line 469, in handle_exception
    self.raise_uncaught_exception(exc)
  File "/root/.local/lib/python3.8/site-packages/rest_framework/views.py", line 480, in raise_uncaught_exception
    raise exc
  File "/root/.local/lib/python3.8/site-packages/rest_framework/views.py", line 506, in dispatch
    response = handler(request, *args, **kwargs)
  File "/app/Professor_Student_Manage/views.py", line 114, in post
    res = requests.get(url, params=params)
  File "/usr/lib/python3.8/site-packages/requests/api.py", line 76, in get
    return request('get', url, params=params, **kwargs)
  File "/usr/lib/python3.8/site-packages/requests/api.py", line 61, in request
    return session.request(method=method, url=url, **kwargs)
  File "/usr/lib/python3.8/site-packages/requests/sessions.py", line 542, in request
    resp = self.send(prep, **send_kwargs)
  File "/usr/lib/python3.8/site-packages/requests/sessions.py", line 655, in send
    r = adapter.send(request, **kwargs)
  File "/usr/lib/python3.8/site-packages/requests/adapters.py", line 516, in send
    raise ConnectionError(e, request=request)
requests.exceptions.ConnectionError: HTTPSConnectionPool(host='api.weixin.qq.com', port=443): Max retries exceeded with url: /sns/jscode2session?appid=wxa67ae78c4f1f6275&secret=7241b1950145a193f15b3584d50f3989&js_code=0d1p5k100DUhUS1E9M3005bvUd3p5k1r&grant_type=authorization_code (Caused by NewConnectionError('<urllib3.connection.HTTPSConnection object at 0xffff83bdabb0>: Failed to establish a new connection: [Errno 111] Connection refused'))
[2024-09-25 08:33:49,165] [basehttp.py:161] [basehttp:log_message] [ERROR]- "POST /userlogin/ HTTP/1.1" 500 181817
[2024-09-25 08:34:34,288] [log.py:224] [log:log_response] [ERROR]- Internal Server Error: /userlogin/
Traceback (most recent call last):
  File "/usr/lib/python3.8/site-packages/urllib3/connection.py", line 169, in _new_conn
    conn = connection.create_connection(
  File "/usr/lib/python3.8/site-packages/urllib3/util/connection.py", line 96, in create_connection
    raise err
  File "/usr/lib/python3.8/site-packages/urllib3/util/connection.py", line 86, in create_connection
    sock.connect(sa)
ConnectionRefusedError: [Errno 111] Connection refused

During handling of the above exception, another exception occurred:

Traceback (most recent call last):
  File "/usr/lib/python3.8/site-packages/urllib3/connectionpool.py", line 699, in urlopen
    httplib_response = self._make_request(
  File "/usr/lib/python3.8/site-packages/urllib3/connectionpool.py", line 382, in _make_request
    self._validate_conn(conn)
  File "/usr/lib/python3.8/site-packages/urllib3/connectionpool.py", line 1010, in _validate_conn
    conn.connect()
  File "/usr/lib/python3.8/site-packages/urllib3/connection.py", line 353, in connect
    conn = self._new_conn()
  File "/usr/lib/python3.8/site-packages/urllib3/connection.py", line 181, in _new_conn
    raise NewConnectionError(
urllib3.exceptions.NewConnectionError: <urllib3.connection.HTTPSConnection object at 0xffff83bca4f0>: Failed to establish a new connection: [Errno 111] Connection refused

During handling of the above exception, another exception occurred:

Traceback (most recent call last):
  File "/usr/lib/python3.8/site-packages/requests/adapters.py", line 439, in send
    resp = conn.urlopen(
  File "/usr/lib/python3.8/site-packages/urllib3/connectionpool.py", line 755, in urlopen
    retries = retries.increment(
  File "/usr/lib/python3.8/site-packages/urllib3/util/retry.py", line 573, in increment
    raise MaxRetryError(_pool, url, error or ResponseError(cause))
urllib3.exceptions.MaxRetryError: HTTPSConnectionPool(host='api.weixin.qq.com', port=443): Max retries exceeded with url: /sns/jscode2session?appid=wxa67ae78c4f1f6275&secret=7241b1950145a193f15b3584d50f3989&js_code=0b1aZu000NEUSS1QWR200Krhja0aZu0q&grant_type=authorization_code (Caused by NewConnectionError('<urllib3.connection.HTTPSConnection object at 0xffff83bca4f0>: Failed to establish a new connection: [Errno 111] Connection refused'))

During handling of the above exception, another exception occurred:

Traceback (most recent call last):
  File "/root/.local/lib/python3.8/site-packages/django/core/handlers/exception.py", line 47, in inner
    response = get_response(request)
  File "/root/.local/lib/python3.8/site-packages/django/core/handlers/base.py", line 181, in _get_response
    response = wrapped_callback(request, *callback_args, **callback_kwargs)
  File "/root/.local/lib/python3.8/site-packages/django/views/decorators/csrf.py", line 54, in wrapped_view
    return view_func(*args, **kwargs)
  File "/root/.local/lib/python3.8/site-packages/django/views/generic/base.py", line 70, in view
    return self.dispatch(request, *args, **kwargs)
  File "/root/.local/lib/python3.8/site-packages/rest_framework/views.py", line 509, in dispatch
    response = self.handle_exception(exc)
  File "/root/.local/lib/python3.8/site-packages/rest_framework/views.py", line 469, in handle_exception
    self.raise_uncaught_exception(exc)
  File "/root/.local/lib/python3.8/site-packages/rest_framework/views.py", line 480, in raise_uncaught_exception
    raise exc
  File "/root/.local/lib/python3.8/site-packages/rest_framework/views.py", line 506, in dispatch
    response = handler(request, *args, **kwargs)
  File "/app/Professor_Student_Manage/views.py", line 114, in post
    res = requests.get(url, params=params)
  File "/usr/lib/python3.8/site-packages/requests/api.py", line 76, in get
    return request('get', url, params=params, **kwargs)
  File "/usr/lib/python3.8/site-packages/requests/api.py", line 61, in request
    return session.request(method=method, url=url, **kwargs)
  File "/usr/lib/python3.8/site-packages/requests/sessions.py", line 542, in request
    resp = self.send(prep, **send_kwargs)
  File "/usr/lib/python3.8/site-packages/requests/sessions.py", line 655, in send
    r = adapter.send(request, **kwargs)
  File "/usr/lib/python3.8/site-packages/requests/adapters.py", line 516, in send
    raise ConnectionError(e, request=request)
requests.exceptions.ConnectionError: HTTPSConnectionPool(host='api.weixin.qq.com', port=443): Max retries exceeded with url: /sns/jscode2session?appid=wxa67ae78c4f1f6275&secret=7241b1950145a193f15b3584d50f3989&js_code=0b1aZu000NEUSS1QWR200Krhja0aZu0q&grant_type=authorization_code (Caused by NewConnectionError('<urllib3.connection.HTTPSConnection object at 0xffff83bca4f0>: Failed to establish a new connection: [Errno 111] Connection refused'))
[2024-09-25 08:34:34,290] [basehttp.py:161] [basehttp:log_message] [ERROR]- "POST /userlogin/ HTTP/1.1" 500 180961
[2024-09-25 08:35:11,820] [basehttp.py:161] [basehttp:log_message] [INFO]- "POST /userlogin/ HTTP/1.1" 200 722
[2024-09-25 08:35:12,344] [basehttp.py:161] [basehttp:log_message] [INFO]- "GET /Professor_Student_Manage/user-info/?usertype=professor HTTP/1.1" 200 636
[2024-09-25 08:35:12,758] [basehttp.py:161] [basehttp:log_message] [INFO]- "GET /Professor_Student_Manage/user-info/?usertype=professor HTTP/1.1" 200 636
[2024-09-25 08:35:16,301] [basehttp.py:161] [basehttp:log_message] [INFO]- "GET /Professor_Student_Manage/user-info/?usertype=professor HTTP/1.1" 200 636
[2024-09-25 08:35:16,724] [basehttp.py:161] [basehttp:log_message] [INFO]- "GET /Professor_Student_Manage/user-info/?usertype=professor HTTP/1.1" 200 636
[2024-09-25 08:35:20,563] [basehttp.py:161] [basehttp:log_message] [INFO]- "GET /Select_Information/get-select-info/?usertype=professor HTTP/1.1" 200 63827
[2024-09-25 08:35:26,393] [basehttp.py:161] [basehttp:log_message] [INFO]- "GET /Select_Information/get-select-info/?usertype=professor HTTP/1.1" 200 63827
[2024-09-25 08:42:19,022] [basehttp.py:161] [basehttp:log_message] [INFO]- "GET /Select_Information/get-select-time/ HTTP/1.1" 200 91
[2024-09-25 08:42:19,340] [basehttp.py:161] [basehttp:log_message] [INFO]- "GET /Select_Information/get-select-time/ HTTP/1.1" 200 91
[2024-09-25 08:42:23,262] [basehttp.py:161] [basehttp:log_message] [INFO]- "GET /Professor_Student_Manage/user-info/?usertype=professor HTTP/1.1" 200 636
[2024-09-25 08:42:23,622] [basehttp.py:161] [basehttp:log_message] [INFO]- "GET /Professor_Student_Manage/professors_and_departments/ HTTP/1.1" 200 82409
[2024-09-25 08:42:27,563] [basehttp.py:161] [basehttp:log_message] [INFO]- "GET /Professor_Student_Manage/user-info/?usertype=professor HTTP/1.1" 200 636
[2024-09-25 08:42:29,836] [basehttp.py:161] [basehttp:log_message] [INFO]- "GET /Professor_Student_Manage/user-info/?usertype=professor HTTP/1.1" 200 636
[2024-09-25 08:42:32,660] [basehttp.py:161] [basehttp:log_message] [INFO]- "GET /Professor_Student_Manage/professors-enrollinfo/?professor_id=131 HTTP/1.1" 200 800
[2024-09-25 08:42:34,502] [basehttp.py:161] [basehttp:log_message] [INFO]- "GET /Select_Information/get-select-info/?usertype=professor HTTP/1.1" 200 63827
[2024-09-25 08:42:35,152] [basehttp.py:161] [basehttp:log_message] [INFO]- "GET /Professor_Student_Manage/professors_and_departments/ HTTP/1.1" 200 82409
[2024-09-25 08:42:49,638] [basehttp.py:161] [basehttp:log_message] [INFO]- "POST /Professor_Student_Manage/submit-quota/ HTTP/1.1" 200 32
[2024-09-25 08:42:51,554] [basehttp.py:161] [basehttp:log_message] [INFO]- "GET /Professor_Student_Manage/user-info/?usertype=professor HTTP/1.1" 200 656
[2024-09-25 08:42:53,076] [basehttp.py:161] [basehttp:log_message] [INFO]- "GET /Professor_Student_Manage/user-info/?usertype=professor HTTP/1.1" 200 656
[2024-09-25 08:42:57,614] [basehttp.py:161] [basehttp:log_message] [INFO]- "GET /Select_Information/get-select-info/?usertype=professor HTTP/1.1" 200 68692
[2024-09-25 08:43:17,940] [log.py:224] [log:log_response] [ERROR]- Internal Server Error: /Professor_Student_Manage/update-professor/
Traceback (most recent call last):
  File "/usr/lib/python3.8/site-packages/urllib3/connection.py", line 169, in _new_conn
    conn = connection.create_connection(
  File "/usr/lib/python3.8/site-packages/urllib3/util/connection.py", line 96, in create_connection
    raise err
  File "/usr/lib/python3.8/site-packages/urllib3/util/connection.py", line 86, in create_connection
    sock.connect(sa)
ConnectionRefusedError: [Errno 111] Connection refused

During handling of the above exception, another exception occurred:

Traceback (most recent call last):
  File "/usr/lib/python3.8/site-packages/urllib3/connectionpool.py", line 699, in urlopen
    httplib_response = self._make_request(
  File "/usr/lib/python3.8/site-packages/urllib3/connectionpool.py", line 382, in _make_request
    self._validate_conn(conn)
  File "/usr/lib/python3.8/site-packages/urllib3/connectionpool.py", line 1010, in _validate_conn
    conn.connect()
  File "/usr/lib/python3.8/site-packages/urllib3/connection.py", line 353, in connect
    conn = self._new_conn()
  File "/usr/lib/python3.8/site-packages/urllib3/connection.py", line 181, in _new_conn
    raise NewConnectionError(
urllib3.exceptions.NewConnectionError: <urllib3.connection.HTTPSConnection object at 0xffff8388d100>: Failed to establish a new connection: [Errno 111] Connection refused

During handling of the above exception, another exception occurred:

Traceback (most recent call last):
  File "/usr/lib/python3.8/site-packages/requests/adapters.py", line 439, in send
    resp = conn.urlopen(
  File "/usr/lib/python3.8/site-packages/urllib3/connectionpool.py", line 755, in urlopen
    retries = retries.increment(
  File "/usr/lib/python3.8/site-packages/urllib3/util/retry.py", line 573, in increment
    raise MaxRetryError(_pool, url, error or ResponseError(cause))
urllib3.exceptions.MaxRetryError: HTTPSConnectionPool(host='api.weixin.qq.com', port=443): Max retries exceeded with url: /tcb/batchdownloadfile (Caused by NewConnectionError('<urllib3.connection.HTTPSConnection object at 0xffff8388d100>: Failed to establish a new connection: [Errno 111] Connection refused'))

During handling of the above exception, another exception occurred:

Traceback (most recent call last):
  File "/root/.local/lib/python3.8/site-packages/django/core/handlers/exception.py", line 47, in inner
    response = get_response(request)
  File "/root/.local/lib/python3.8/site-packages/django/core/handlers/base.py", line 181, in _get_response
    response = wrapped_callback(request, *callback_args, **callback_kwargs)
  File "/root/.local/lib/python3.8/site-packages/django/views/decorators/csrf.py", line 54, in wrapped_view
    return view_func(*args, **kwargs)
  File "/root/.local/lib/python3.8/site-packages/django/views/generic/base.py", line 70, in view
    return self.dispatch(request, *args, **kwargs)
  File "/root/.local/lib/python3.8/site-packages/rest_framework/views.py", line 509, in dispatch
    response = self.handle_exception(exc)
  File "/root/.local/lib/python3.8/site-packages/rest_framework/views.py", line 469, in handle_exception
    self.raise_uncaught_exception(exc)
  File "/root/.local/lib/python3.8/site-packages/rest_framework/views.py", line 480, in raise_uncaught_exception
    raise exc
  File "/root/.local/lib/python3.8/site-packages/rest_framework/views.py", line 506, in dispatch
    response = handler(request, *args, **kwargs)
  File "/app/Professor_Student_Manage/views.py", line 202, in patch
    response = requests.post(url, json=data)
  File "/usr/lib/python3.8/site-packages/requests/api.py", line 119, in post
    return request('post', url, data=data, json=json, **kwargs)
  File "/usr/lib/python3.8/site-packages/requests/api.py", line 61, in request
    return session.request(method=method, url=url, **kwargs)
  File "/usr/lib/python3.8/site-packages/requests/sessions.py", line 542, in request
    resp = self.send(prep, **send_kwargs)
  File "/usr/lib/python3.8/site-packages/requests/sessions.py", line 655, in send
    r = adapter.send(request, **kwargs)
  File "/usr/lib/python3.8/site-packages/requests/adapters.py", line 516, in send
    raise ConnectionError(e, request=request)
requests.exceptions.ConnectionError: HTTPSConnectionPool(host='api.weixin.qq.com', port=443): Max retries exceeded with url: /tcb/batchdownloadfile (Caused by NewConnectionError('<urllib3.connection.HTTPSConnection object at 0xffff8388d100>: Failed to establish a new connection: [Errno 111] Connection refused'))
[2024-09-25 08:43:17,943] [basehttp.py:161] [basehttp:log_message] [ERROR]- "PATCH /Professor_Student_Manage/update-professor/ HTTP/1.1" 500 179932
[2024-09-25 08:43:18,395] [basehttp.py:161] [basehttp:log_message] [INFO]- "GET /Professor_Student_Manage/user-info/?usertype=professor HTTP/1.1" 200 656
[2024-09-25 08:43:22,949] [basehttp.py:161] [basehttp:log_message] [INFO]- "GET /Select_Information/get-select-info/?usertype=professor HTTP/1.1" 200 68692
[2024-09-25 08:47:37,842] [autoreload.py:637] [autoreload:run_with_reloader] [INFO]- Watching for file changes with StatReloader
[2024-09-25 08:47:47,723] [basehttp.py:161] [basehttp:log_message] [INFO]- "GET /Select_Information/get-select-info/?usertype=professor HTTP/1.1" 200 68692
[2024-09-25 08:47:49,162] [basehttp.py:161] [basehttp:log_message] [INFO]- "GET /Professor_Student_Manage/user-info/?usertype=professor HTTP/1.1" 200 656
[2024-09-25 08:47:50,045] [basehttp.py:161] [basehttp:log_message] [INFO]- "PATCH /Professor_Student_Manage/update-professor/ HTTP/1.1" 200 236
[2024-09-25 08:47:53,996] [basehttp.py:161] [basehttp:log_message] [INFO]- "GET /Select_Information/get-select-info/?usertype=professor HTTP/1.1" 200 68692
[2024-09-25 08:53:11,209] [autoreload.py:637] [autoreload:run_with_reloader] [INFO]- Watching for file changes with StatReloader
[2024-09-25 08:53:18,472] [basehttp.py:161] [basehttp:log_message] [INFO]- "PATCH /Professor_Student_Manage/update-professor/ HTTP/1.1" 200 236
[2024-09-25 08:53:18,506] [basehttp.py:161] [basehttp:log_message] [INFO]- "GET /Professor_Student_Manage/user-info/?usertype=professor HTTP/1.1" 200 656
[2024-09-25 08:53:23,169] [basehttp.py:161] [basehttp:log_message] [INFO]- "GET /Select_Information/get-select-info/?usertype=professor HTTP/1.1" 200 68692
[2024-09-25 09:16:59,976] [autoreload.py:637] [autoreload:run_with_reloader] [INFO]- Watching for file changes with StatReloader
[2024-09-25 09:30:30,780] [autoreload.py:637] [autoreload:run_with_reloader] [INFO]- Watching for file changes with StatReloader
[2024-09-25 09:30:31,838] [autoreload.py:637] [autoreload:run_with_reloader] [INFO]- Watching for file changes with StatReloader
[2024-09-25 09:31:06,498] [autoreload.py:637] [autoreload:run_with_reloader] [INFO]- Watching for file changes with StatReloader
[2024-09-25 09:37:19,144] [basehttp.py:161] [basehttp:log_message] [INFO]- "GET /Select_Information/get-select-info/?usertype=professor HTTP/1.1" 200 68692
[2024-09-25 09:46:02,026] [autoreload.py:637] [autoreload:run_with_reloader] [INFO]- Watching for file changes with StatReloader
[2024-09-25 09:46:13,242] [autoreload.py:637] [autoreload:run_with_reloader] [INFO]- Watching for file changes with StatReloader
[2024-09-25 09:57:52,199] [autoreload.py:637] [autoreload:run_with_reloader] [INFO]- Watching for file changes with StatReloader
[2024-09-25 10:08:23,533] [autoreload.py:637] [autoreload:run_with_reloader] [INFO]- Watching for file changes with StatReloader
[2024-09-25 10:08:58,080] [basehttp.py:161] [basehttp:log_message] [INFO]- "POST /userlogin/ HTTP/1.1" 200 742
[2024-09-25 10:08:58,672] [basehttp.py:161] [basehttp:log_message] [INFO]- "GET /Professor_Student_Manage/user-info/?usertype=professor HTTP/1.1" 200 656
[2024-09-25 10:08:59,080] [basehttp.py:161] [basehttp:log_message] [INFO]- "GET /Professor_Student_Manage/user-info/?usertype=professor HTTP/1.1" 200 656
[2024-09-25 10:09:01,111] [basehttp.py:161] [basehttp:log_message] [INFO]- "GET /Professor_Student_Manage/user-info/?usertype=professor HTTP/1.1" 200 656
[2024-09-25 10:09:01,528] [basehttp.py:161] [basehttp:log_message] [INFO]- "GET /Professor_Student_Manage/user-info/?usertype=professor HTTP/1.1" 200 656
[2024-09-25 10:09:05,501] [basehttp.py:161] [basehttp:log_message] [INFO]- "GET /Select_Information/get-select-info/?usertype=professor HTTP/1.1" 200 68692
[2024-09-25 10:09:11,869] [basehttp.py:161] [basehttp:log_message] [INFO]- "GET /Select_Information/get-select-info/?usertype=professor HTTP/1.1" 200 68692
[2024-09-25 10:09:16,513] [basehttp.py:161] [basehttp:log_message] [INFO]- "GET /Professor_Student_Manage/user-info/?usertype=professor HTTP/1.1" 200 656
[2024-09-25 10:09:16,711] [log.py:224] [log:log_response] [ERROR]- Internal Server Error: /Professor_Student_Manage/update-professor/
[2024-09-25 10:09:16,711] [basehttp.py:161] [basehttp:log_message] [ERROR]- "PATCH /Professor_Student_Manage/update-professor/ HTTP/1.1" 500 98
[2024-09-25 10:09:16,785] [basehttp.py:161] [basehttp:log_message] [INFO]- "GET /Select_Information/get-select-info/?usertype=professor HTTP/1.1" 200 68692
[2024-09-25 10:09:21,782] [basehttp.py:161] [basehttp:log_message] [INFO]- "GET /Select_Information/get-select-info/?usertype=professor HTTP/1.1" 200 68692
[2024-09-25 10:10:14,701] [autoreload.py:637] [autoreload:run_with_reloader] [INFO]- Watching for file changes with StatReloader
[2024-09-25 10:10:21,950] [basehttp.py:161] [basehttp:log_message] [INFO]- "GET /Professor_Student_Manage/user-info/?usertype=professor HTTP/1.1" 200 656
[2024-09-25 10:10:22,008] [log.py:224] [log:log_response] [ERROR]- Internal Server Error: /Professor_Student_Manage/update-professor/
[2024-09-25 10:10:22,008] [basehttp.py:161] [basehttp:log_message] [ERROR]- "PATCH /Professor_Student_Manage/update-professor/ HTTP/1.1" 500 98
[2024-09-25 10:10:26,548] [basehttp.py:161] [basehttp:log_message] [INFO]- "GET /Select_Information/get-select-info/?usertype=professor HTTP/1.1" 200 68692
[2024-09-25 10:11:13,030] [autoreload.py:637] [autoreload:run_with_reloader] [INFO]- Watching for file changes with StatReloader
[2024-09-25 10:11:20,586] [basehttp.py:161] [basehttp:log_message] [INFO]- "GET /Professor_Student_Manage/user-info/?usertype=professor HTTP/1.1" 200 656
[2024-09-25 10:11:20,980] [log.py:224] [log:log_response] [ERROR]- Internal Server Error: /Professor_Student_Manage/update-professor/
[2024-09-25 10:11:20,981] [basehttp.py:161] [basehttp:log_message] [ERROR]- "PATCH /Professor_Student_Manage/update-professor/ HTTP/1.1" 500 98
[2024-09-25 10:11:25,104] [basehttp.py:161] [basehttp:log_message] [INFO]- "GET /Select_Information/get-select-info/?usertype=professor HTTP/1.1" 200 68692
[2024-09-25 10:12:22,391] [autoreload.py:637] [autoreload:run_with_reloader] [INFO]- Watching for file changes with StatReloader
[2024-09-25 10:12:29,260] [log.py:224] [log:log_response] [ERROR]- Internal Server Error: /Professor_Student_Manage/update-professor/
[2024-09-25 10:12:29,260] [basehttp.py:161] [basehttp:log_message] [ERROR]- "PATCH /Professor_Student_Manage/update-professor/ HTTP/1.1" 500 98
[2024-09-25 10:12:29,328] [basehttp.py:161] [basehttp:log_message] [INFO]- "GET /Professor_Student_Manage/user-info/?usertype=professor HTTP/1.1" 200 656
[2024-09-25 10:12:34,095] [basehttp.py:161] [basehttp:log_message] [INFO]- "GET /Select_Information/get-select-info/?usertype=professor HTTP/1.1" 200 68692
[2024-09-25 10:15:00,501] [autoreload.py:637] [autoreload:run_with_reloader] [INFO]- Watching for file changes with StatReloader
[2024-09-25 10:15:37,654] [autoreload.py:637] [autoreload:run_with_reloader] [INFO]- Watching for file changes with StatReloader
[2024-09-25 10:15:46,007] [basehttp.py:161] [basehttp:log_message] [INFO]- "GET /Professor_Student_Manage/user-info/?usertype=professor HTTP/1.1" 200 656
[2024-09-25 10:15:47,525] [log.py:224] [log:log_response] [ERROR]- Internal Server Error: /Professor_Student_Manage/update-professor/
[2024-09-25 10:15:47,526] [basehttp.py:161] [basehttp:log_message] [ERROR]- "PATCH /Professor_Student_Manage/update-professor/ HTTP/1.1" 500 69
[2024-09-25 10:15:51,346] [basehttp.py:161] [basehttp:log_message] [INFO]- "GET /Select_Information/get-select-info/?usertype=professor HTTP/1.1" 200 68692
[2024-09-25 10:16:26,968] [autoreload.py:637] [autoreload:run_with_reloader] [INFO]- Watching for file changes with StatReloader
[2024-09-25 10:16:46,066] [autoreload.py:637] [autoreload:run_with_reloader] [INFO]- Watching for file changes with StatReloader
[2024-09-25 10:41:02,337] [autoreload.py:637] [autoreload:run_with_reloader] [INFO]- Watching for file changes with StatReloader
[2024-09-25 10:42:40,426] [autoreload.py:637] [autoreload:run_with_reloader] [INFO]- Watching for file changes with StatReloader
[2024-09-25 10:42:50,067] [autoreload.py:637] [autoreload:run_with_reloader] [INFO]- Watching for file changes with StatReloader
[2024-09-25 10:45:40,935] [autoreload.py:637] [autoreload:run_with_reloader] [INFO]- Watching for file changes with StatReloader
[2024-09-25 10:46:26,272] [autoreload.py:637] [autoreload:run_with_reloader] [INFO]- Watching for file changes with StatReloader
[2024-09-25 10:46:30,419] [autoreload.py:637] [autoreload:run_with_reloader] [INFO]- Watching for file changes with StatReloader
[2024-09-25 10:46:39,996] [basehttp.py:161] [basehttp:log_message] [INFO]- "GET /Professor_Student_Manage/user-info/?usertype=professor HTTP/1.1" 200 656
[2024-09-25 10:46:40,642] [basehttp.py:161] [basehttp:log_message] [INFO]- "GET /Professor_Student_Manage/user-info/?usertype=professor HTTP/1.1" 200 656
[2024-09-25 10:46:44,569] [basehttp.py:161] [basehttp:log_message] [INFO]- "GET /Select_Information/get-select-info/?usertype=professor HTTP/1.1" 200 68692
[2024-09-25 10:46:50,095] [basehttp.py:161] [basehttp:log_message] [INFO]- "GET /Select_Information/get-select-info/?usertype=professor HTTP/1.1" 200 68692
[2024-09-25 10:49:04,743] [autoreload.py:637] [autoreload:run_with_reloader] [INFO]- Watching for file changes with StatReloader
[2024-09-25 10:54:19,903] [basehttp.py:161] [basehttp:log_message] [INFO]- "GET /Professor_Student_Manage/user-info/?usertype=professor HTTP/1.1" 200 656
[2024-09-25 10:54:20,349] [basehttp.py:161] [basehttp:log_message] [INFO]- "GET /Professor_Student_Manage/user-info/?usertype=professor HTTP/1.1" 200 656
[2024-09-25 10:54:20,722] [basehttp.py:161] [basehttp:log_message] [INFO]- "GET /Professor_Student_Manage/user-info/?usertype=professor HTTP/1.1" 200 656
[2024-09-25 10:54:21,098] [basehttp.py:161] [basehttp:log_message] [INFO]- "GET /Professor_Student_Manage/user-info/?usertype=professor HTTP/1.1" 200 656
[2024-09-25 10:54:24,528] [basehttp.py:161] [basehttp:log_message] [INFO]- "GET /Select_Information/get-select-info/?usertype=professor HTTP/1.1" 200 68692
[2024-09-25 10:54:26,951] [basehttp.py:161] [basehttp:log_message] [INFO]- "GET /Select_Information/get-select-info/?usertype=professor HTTP/1.1" 200 68692
[2024-09-25 10:56:54,515] [autoreload.py:251] [autoreload:trigger_reload] [INFO]- /app/Professor_Student_Manage/views.py changed, reloading.
[2024-09-25 10:56:55,020] [autoreload.py:637] [autoreload:run_with_reloader] [INFO]- Watching for file changes with StatReloader
[2024-09-25 10:59:09,788] [autoreload.py:251] [autoreload:trigger_reload] [INFO]- /app/Professor_Student_Manage/views.py changed, reloading.
[2024-09-25 10:59:10,293] [autoreload.py:637] [autoreload:run_with_reloader] [INFO]- Watching for file changes with StatReloader
[2024-09-25 11:00:50,381] [autoreload.py:637] [autoreload:run_with_reloader] [INFO]- Watching for file changes with StatReloader
[2024-09-25 11:04:36,805] [autoreload.py:637] [autoreload:run_with_reloader] [INFO]- Watching for file changes with StatReloader
[2024-09-25 11:04:38,414] [autoreload.py:637] [autoreload:run_with_reloader] [INFO]- Watching for file changes with StatReloader
[2024-09-25 11:11:21,773] [autoreload.py:637] [autoreload:run_with_reloader] [INFO]- Watching for file changes with StatReloader
[2024-09-25 11:12:50,689] [autoreload.py:637] [autoreload:run_with_reloader] [INFO]- Watching for file changes with StatReloader
[2024-09-25 11:13:02,819] [basehttp.py:161] [basehttp:log_message] [INFO]- "POST /userlogin/ HTTP/1.1" 200 742
[2024-09-25 11:13:03,328] [basehttp.py:161] [basehttp:log_message] [INFO]- "GET /Professor_Student_Manage/user-info/?usertype=professor HTTP/1.1" 200 656
[2024-09-25 11:13:03,738] [basehttp.py:161] [basehttp:log_message] [INFO]- "GET /Professor_Student_Manage/user-info/?usertype=professor HTTP/1.1" 200 656
[2024-09-25 11:13:05,083] [basehttp.py:161] [basehttp:log_message] [INFO]- "GET /Professor_Student_Manage/user-info/?usertype=professor HTTP/1.1" 200 656
[2024-09-25 11:13:05,494] [basehttp.py:161] [basehttp:log_message] [INFO]- "GET /Professor_Student_Manage/user-info/?usertype=professor HTTP/1.1" 200 656
[2024-09-25 11:13:09,738] [basehttp.py:161] [basehttp:log_message] [INFO]- "GET /Select_Information/get-select-info/?usertype=professor HTTP/1.1" 200 68692
[2024-09-25 11:13:15,475] [basehttp.py:161] [basehttp:log_message] [INFO]- "GET /Select_Information/get-select-info/?usertype=professor HTTP/1.1" 200 68692
[2024-09-25 11:13:18,334] [basehttp.py:161] [basehttp:log_message] [INFO]- "GET /Professor_Student_Manage/user-info/?usertype=professor HTTP/1.1" 200 656
[2024-09-25 11:13:19,512] [log.py:224] [log:log_response] [ERROR]- Internal Server Error: /Professor_Student_Manage/update-professor/
[2024-09-25 11:13:19,513] [basehttp.py:161] [basehttp:log_message] [ERROR]- "PATCH /Professor_Student_Manage/update-professor/ HTTP/1.1" 500 69
[2024-09-25 11:13:22,951] [basehttp.py:161] [basehttp:log_message] [INFO]- "GET /Select_Information/get-select-info/?usertype=professor HTTP/1.1" 200 68692
[2024-09-25 11:14:05,999] [autoreload.py:637] [autoreload:run_with_reloader] [INFO]- Watching for file changes with StatReloader
[2024-09-25 11:14:12,522] [basehttp.py:161] [basehttp:log_message] [INFO]- "GET /Professor_Student_Manage/user-info/?usertype=professor HTTP/1.1" 200 656
[2024-09-25 11:14:13,456] [log.py:224] [log:log_response] [ERROR]- Internal Server Error: /Professor_Student_Manage/update-professor/
[2024-09-25 11:14:13,457] [basehttp.py:161] [basehttp:log_message] [ERROR]- "PATCH /Professor_Student_Manage/update-professor/ HTTP/1.1" 500 69
[2024-09-25 11:14:18,637] [basehttp.py:161] [basehttp:log_message] [INFO]- "GET /Select_Information/get-select-info/?usertype=professor HTTP/1.1" 200 68692
[2024-09-25 11:14:28,006] [autoreload.py:637] [autoreload:run_with_reloader] [INFO]- Watching for file changes with StatReloader
[2024-09-25 11:14:30,737] [autoreload.py:637] [autoreload:run_with_reloader] [INFO]- Watching for file changes with StatReloader
[2024-09-25 11:14:37,451] [autoreload.py:637] [autoreload:run_with_reloader] [INFO]- Watching for file changes with StatReloader
[2024-09-25 11:14:47,830] [basehttp.py:161] [basehttp:log_message] [INFO]- "GET /Professor_Student_Manage/user-info/?usertype=professor HTTP/1.1" 200 656
[2024-09-25 11:14:48,345] [basehttp.py:161] [basehttp:log_message] [INFO]- "GET /Professor_Student_Manage/user-info/?usertype=professor HTTP/1.1" 200 656
[2024-09-25 11:14:48,736] [basehttp.py:161] [basehttp:log_message] [INFO]- "GET /Professor_Student_Manage/user-info/?usertype=professor HTTP/1.1" 200 656
[2024-09-25 11:14:49,189] [basehttp.py:161] [basehttp:log_message] [INFO]- "GET /Professor_Student_Manage/user-info/?usertype=professor HTTP/1.1" 200 656
[2024-09-25 11:14:53,070] [basehttp.py:161] [basehttp:log_message] [INFO]- "GET /Select_Information/get-select-info/?usertype=professor HTTP/1.1" 200 68692
[2024-09-25 11:16:14,112] [autoreload.py:637] [autoreload:run_with_reloader] [INFO]- Watching for file changes with StatReloader
[2024-09-25 11:16:58,244] [autoreload.py:637] [autoreload:run_with_reloader] [INFO]- Watching for file changes with StatReloader
[2024-09-25 11:31:07,602] [autoreload.py:637] [autoreload:run_with_reloader] [INFO]- Watching for file changes with StatReloader
[2024-09-25 15:14:31,016] [autoreload.py:637] [autoreload:run_with_reloader] [INFO]- Watching for file changes with StatReloader
[2024-09-25 15:19:30,546] [basehttp.py:161] [basehttp:log_message] [INFO]- "POST /userlogin/ HTTP/1.1" 200 742
[2024-09-25 15:19:31,043] [basehttp.py:161] [basehttp:log_message] [INFO]- "GET /Professor_Student_Manage/user-info/?usertype=professor HTTP/1.1" 200 656
[2024-09-25 15:19:31,497] [basehttp.py:161] [basehttp:log_message] [INFO]- "GET /Professor_Student_Manage/user-info/?usertype=professor HTTP/1.1" 200 656
[2024-09-25 15:19:33,437] [basehttp.py:161] [basehttp:log_message] [INFO]- "GET /Professor_Student_Manage/user-info/?usertype=professor HTTP/1.1" 200 656
[2024-09-25 15:19:33,848] [basehttp.py:161] [basehttp:log_message] [INFO]- "GET /Professor_Student_Manage/user-info/?usertype=professor HTTP/1.1" 200 656
[2024-09-25 15:19:37,898] [basehttp.py:161] [basehttp:log_message] [INFO]- "GET /Select_Information/get-select-info/?usertype=professor HTTP/1.1" 200 68692
[2024-09-25 15:19:44,351] [basehttp.py:161] [basehttp:log_message] [INFO]- "GET /Select_Information/get-select-info/?usertype=professor HTTP/1.1" 200 68692
[2024-09-25 15:19:51,726] [autoreload.py:637] [autoreload:run_with_reloader] [INFO]- Watching for file changes with StatReloader
[2024-09-25 15:19:53,202] [autoreload.py:637] [autoreload:run_with_reloader] [INFO]- Watching for file changes with StatReloader
[2024-09-25 15:19:55,374] [basehttp.py:161] [basehttp:log_message] [INFO]- "GET /Professor_Student_Manage/student-resumeinfo/?student_id=250 HTTP/1.1" 200 308
[2024-09-25 15:19:56,735] [basehttp.py:161] [basehttp:log_message] [INFO]- "GET /Professor_Student_Manage/user-info/?usertype=professor HTTP/1.1" 200 656
[2024-09-25 15:20:01,057] [basehttp.py:161] [basehttp:log_message] [INFO]- "GET /Select_Information/get-select-info/?usertype=professor HTTP/1.1" 200 68692
[2024-09-25 15:21:40,190] [basehttp.py:161] [basehttp:log_message] [INFO]- "GET /Professor_Student_Manage/user-info/?usertype=professor HTTP/1.1" 200 656
[2024-09-25 15:21:40,622] [basehttp.py:161] [basehttp:log_message] [INFO]- "GET /Professor_Student_Manage/user-info/?usertype=professor HTTP/1.1" 200 656
[2024-09-25 15:21:44,822] [basehttp.py:161] [basehttp:log_message] [INFO]- "GET /Select_Information/get-select-info/?usertype=professor HTTP/1.1" 200 68692
[2024-09-25 15:21:48,733] [basehttp.py:161] [basehttp:log_message] [INFO]- "GET /Professor_Student_Manage/student-resumeinfo/?student_id=250 HTTP/1.1" 200 308
[2024-09-25 15:21:50,018] [basehttp.py:161] [basehttp:log_message] [INFO]- "GET /Select_Information/get-select-info/?usertype=professor HTTP/1.1" 200 68692
[2024-09-25 15:21:50,212] [basehttp.py:161] [basehttp:log_message] [INFO]- "GET /Professor_Student_Manage/user-info/?usertype=professor HTTP/1.1" 200 656
[2024-09-25 15:21:54,892] [basehttp.py:161] [basehttp:log_message] [INFO]- "GET /Select_Information/get-select-info/?usertype=professor HTTP/1.1" 200 68692
[2024-09-25 15:22:00,106] [basehttp.py:161] [basehttp:log_message] [INFO]- "GET /Select_Information/get-select-info/?usertype=professor HTTP/1.1" 200 68692
[2024-09-25 15:22:19,100] [basehttp.py:161] [basehttp:log_message] [INFO]- "GET /Professor_Student_Manage/user-info/?usertype=professor HTTP/1.1" 200 656
[2024-09-25 15:22:21,143] [basehttp.py:161] [basehttp:log_message] [INFO]- "POST /Professor_Student_Manage/user-logout/ HTTP/1.1" 200 37
[2024-09-25 15:22:52,602] [basehttp.py:161] [basehttp:log_message] [INFO]- "POST /userlogin/ HTTP/1.1" 200 791
[2024-09-25 15:22:53,136] [basehttp.py:161] [basehttp:log_message] [INFO]- "GET /Professor_Student_Manage/user-info/?usertype=student HTTP/1.1" 200 705
[2024-09-25 15:22:53,505] [basehttp.py:161] [basehttp:log_message] [INFO]- "GET /Professor_Student_Manage/user-info/?usertype=student HTTP/1.1" 200 705
[2024-09-25 15:22:55,989] [basehttp.py:161] [basehttp:log_message] [INFO]- "GET /Professor_Student_Manage/user-info/?usertype=student HTTP/1.1" 200 705
[2024-09-25 15:22:56,110] [basehttp.py:161] [basehttp:log_message] [INFO]- "GET /Select_Information/get-select-info/?usertype=student HTTP/1.1" 200 651
[2024-09-25 15:22:56,370] [basehttp.py:161] [basehttp:log_message] [INFO]- "GET /Professor_Student_Manage/user-info/?usertype=student HTTP/1.1" 200 705
[2024-09-25 15:22:56,592] [basehttp.py:161] [basehttp:log_message] [INFO]- "GET /Select_Information/get-select-info/?usertype=student HTTP/1.1" 200 651
[2024-09-25 15:24:46,557] [basehttp.py:161] [basehttp:log_message] [INFO]- "POST /userlogin/ HTTP/1.1" 200 791
[2024-09-25 15:24:47,061] [basehttp.py:161] [basehttp:log_message] [INFO]- "GET /Professor_Student_Manage/user-info/?usertype=student HTTP/1.1" 200 705
[2024-09-25 15:24:47,437] [basehttp.py:161] [basehttp:log_message] [INFO]- "GET /Professor_Student_Manage/user-info/?usertype=student HTTP/1.1" 200 705
[2024-09-25 15:24:49,076] [basehttp.py:161] [basehttp:log_message] [INFO]- "GET /Professor_Student_Manage/user-info/?usertype=student HTTP/1.1" 200 705
[2024-09-25 15:24:49,197] [basehttp.py:161] [basehttp:log_message] [INFO]- "GET /Select_Information/get-select-info/?usertype=student HTTP/1.1" 200 651
[2024-09-25 15:24:49,472] [basehttp.py:161] [basehttp:log_message] [INFO]- "GET /Professor_Student_Manage/user-info/?usertype=student HTTP/1.1" 200 705
[2024-09-25 15:24:49,703] [basehttp.py:161] [basehttp:log_message] [INFO]- "GET /Select_Information/get-select-info/?usertype=student HTTP/1.1" 200 651
[2024-09-25 15:25:32,438] [basehttp.py:161] [basehttp:log_message] [INFO]- "GET /Professor_Student_Manage/student-resumeinfo/?student_id=250 HTTP/1.1" 200 308
[2024-09-25 15:25:34,027] [basehttp.py:161] [basehttp:log_message] [INFO]- "GET /Professor_Student_Manage/user-info/?usertype=student HTTP/1.1" 200 705
[2024-09-25 15:25:34,154] [basehttp.py:161] [basehttp:log_message] [INFO]- "GET /Select_Information/get-select-info/?usertype=student HTTP/1.1" 200 651
[2024-09-25 15:25:57,799] [autoreload.py:637] [autoreload:run_with_reloader] [INFO]- Watching for file changes with StatReloader
[2024-09-25 15:27:07,096] [autoreload.py:637] [autoreload:run_with_reloader] [INFO]- Watching for file changes with StatReloader
[2024-09-25 15:28:42,512] [basehttp.py:161] [basehttp:log_message] [INFO]- "GET /Professor_Student_Manage/user-info/?usertype=student HTTP/1.1" 200 705
[2024-09-25 15:28:42,652] [basehttp.py:161] [basehttp:log_message] [INFO]- "GET /Select_Information/get-select-info/?usertype=student HTTP/1.1" 200 651
[2024-09-25 15:28:42,925] [basehttp.py:161] [basehttp:log_message] [INFO]- "GET /Professor_Student_Manage/user-info/?usertype=student HTTP/1.1" 200 705
[2024-09-25 15:28:43,124] [basehttp.py:161] [basehttp:log_message] [INFO]- "GET /Select_Information/get-select-info/?usertype=student HTTP/1.1" 200 651
[2024-09-25 15:28:45,505] [basehttp.py:161] [basehttp:log_message] [INFO]- "GET /Professor_Student_Manage/user-info/?usertype=student HTTP/1.1" 200 705
[2024-09-25 15:28:45,893] [basehttp.py:161] [basehttp:log_message] [INFO]- "GET /Professor_Student_Manage/user-info/?usertype=student HTTP/1.1" 200 705
[2024-09-25 15:28:46,774] [basehttp.py:161] [basehttp:log_message] [INFO]- "GET /Professor_Student_Manage/user-info/?usertype=student HTTP/1.1" 200 705
[2024-09-25 15:28:46,888] [basehttp.py:161] [basehttp:log_message] [INFO]- "GET /Select_Information/get-select-info/?usertype=student HTTP/1.1" 200 651
[2024-09-25 15:31:32,017] [autoreload.py:637] [autoreload:run_with_reloader] [INFO]- Watching for file changes with StatReloader
[2024-09-25 15:42:54,629] [autoreload.py:637] [autoreload:run_with_reloader] [INFO]- Watching for file changes with StatReloader
[2024-09-25 15:43:40,787] [autoreload.py:637] [autoreload:run_with_reloader] [INFO]- Watching for file changes with StatReloader
[2024-09-25 15:45:41,465] [autoreload.py:637] [autoreload:run_with_reloader] [INFO]- Watching for file changes with StatReloader
[2024-09-25 15:47:52,522] [basehttp.py:161] [basehttp:log_message] [INFO]- "GET /Professor_Student_Manage/student-resumeinfo/?student_id=250 HTTP/1.1" 200 308
[2024-09-25 15:47:54,366] [basehttp.py:161] [basehttp:log_message] [INFO]- "GET /Professor_Student_Manage/user-info/?usertype=student HTTP/1.1" 200 705
[2024-09-25 15:47:54,426] [basehttp.py:161] [basehttp:log_message] [INFO]- "GET /Select_Information/get-select-info/?usertype=student HTTP/1.1" 200 651
[2024-09-25 15:48:26,029] [basehttp.py:161] [basehttp:log_message] [INFO]- "GET /Select_Information/get-select-info/?usertype=student HTTP/1.1" 200 651
[2024-09-25 17:07:22,167] [basehttp.py:161] [basehttp:log_message] [INFO]- "GET /Select_Information/get-select-info/?usertype=student HTTP/1.1" 200 651
[2024-09-25 17:07:23,858] [basehttp.py:161] [basehttp:log_message] [INFO]- "GET /Select_Information/get-select-time/ HTTP/1.1" 200 91
[2024-09-25 17:07:24,128] [basehttp.py:161] [basehttp:log_message] [INFO]- "GET /Select_Information/get-select-time/ HTTP/1.1" 200 91
[2024-09-25 17:07:28,331] [basehttp.py:161] [basehttp:log_message] [INFO]- "GET /Professor_Student_Manage/professors_and_departments/ HTTP/1.1" 200 82429
[2024-09-25 17:07:35,516] [basehttp.py:161] [basehttp:log_message] [INFO]- "GET /Professor_Student_Manage/professors_and_departments/ HTTP/1.1" 200 82429
[2024-09-25 17:51:14,475] [autoreload.py:637] [autoreload:run_with_reloader] [INFO]- Watching for file changes with StatReloader
[2024-09-25 17:57:00,196] [autoreload.py:637] [autoreload:run_with_reloader] [INFO]- Watching for file changes with StatReloader
[2024-09-25 18:01:21,256] [autoreload.py:637] [autoreload:run_with_reloader] [INFO]- Watching for file changes with StatReloader
[2024-09-25 18:02:21,896] [autoreload.py:637] [autoreload:run_with_reloader] [INFO]- Watching for file changes with StatReloader
[2024-09-25 18:04:44,410] [autoreload.py:637] [autoreload:run_with_reloader] [INFO]- Watching for file changes with StatReloader
[2024-09-25 18:04:45,486] [autoreload.py:637] [autoreload:run_with_reloader] [INFO]- Watching for file changes with StatReloader
